# 株式会社ハートビーツさんから出された課題「lamp環境の構築」の課程3
NTPサーバーの設定に悪戦苦闘したが、たぶん何とかなった。というわけで、次に進む。

## サーバのファイアウォールを起動

とりあえずmanコマンドを試す。

```
$ man firewalld
No manual entry for firewalld
```

firewallをインストールする必要がありそうだ。
'https://firewalld.org/download/'

```
$ git clone https://github.com/firewalld/firewalld.git
Cloning into 'firewalld'...
remote: Enumerating objects: 33019, done.
remote: Counting objects: 100% (2501/2501), done.
remote: Compressing objects: 100% (714/714), done.
remote: Total 33019 (delta 1949), reused 2088 (delta 1780), pack-reused 30518
Receiving objects: 100% (33019/33019), 20.62 MiB | 2.44 MiB/s, done.
Resolving deltas: 100% (26549/26549), done.
Updating files: 100% (672/672), done.
warning: the following paths have collided (e.g. case-sensitive paths
on a case-insensitive filesystem) and only one from the same
colliding group is in the working tree:

  'config/FirewallD.conf'
  'config/firewalld.conf'
```

ダウンロードは出来たみたいだが、警告が出ている。

```
$ man firewalld
No manual entry for firewalld
```

パスが衝突しているとの警告が出ていたので、もしや

```
$ man firewallD
No manual entry for firewallD
```

違ったようだ。
ヒントに"ufw"とあったのでmanを実行。

```
$ man ufw
UFW:(8)                                             September 2021                                            UFW:(8)

NAME
       ufw - program for managing a netfilter firewall

DESCRIPTION
       This program is for managing a Linux firewall and aims to provide an easy to use interface for the user.

USAGE
       ufw [--dry-run] enable|disable|reload

       ufw [--dry-run] default allow|deny|reject [incoming|outgoing|routed]

       ufw [--dry-run] logging on|off|LEVEL

       ufw [--dry-run] reset

       ufw [--dry-run] status [verbose|numbered]

       ufw [--dry-run] show REPORT

       ufw  [--dry-run] [delete] [insert NUM] [prepend] allow|deny|reject|limit [in|out] [log|log-all] [ PORT[/PROTO‐
       COL] | APPNAME ] [comment COMMENT]

       ufw [--dry-run] [rule]  [delete]  [insert  NUM]  [prepend]  allow|deny|reject|limit  [in|out  [on  INTERFACE]]
       [log|log-all]  [proto PROTOCOL] [from ADDRESS [port PORT | app APPNAME ]] [to ADDRESS [port PORT | app APPNAME
       ]] [comment COMMENT]

       ufw  [--dry-run]  route  [delete]  [insert  NUM]  [prepend]  allow|deny|reject|limit  [in|out  on   INTERFACE]
```

> ufw - program for managing a netfilter firewall

firewall関連のファイル、存在しました。

```
$ man firewall-cmd
No manual entry for firewall-cmd
```

ヒントにあったこちらのコマンドも実行したが、空振り。

とりあえず、ufwの状態を確認する。

```
$ sudo ufw status
Status: inactive
```

起動していない。

'https://access.redhat.com/documentation/ja-jp/red_hat_enterprise_linux/8/html/configuring_basic_system_settings/enabling-a-system-service_managing-system-services-with-systemctl'

> システムの起動時にサービスが起動するようにします。
"systemctl enable <name>.service"

なるほど、

```
$ sudo systemctl enable ufw.service
Synchronizing state of ufw.service with SysV service script with /lib/systemd/systemd-sysv-install.
Executing: /lib/systemd/systemd-sysv-install enable ufw
```

なんか蛇道に向かっている気がする。

ubuntuのファイアウォール関連のページを発見。
'https://ubuntu.com/server/docs/security-firewall'

```
$ ufw enable
Traceback (most recent call last):
  File "/usr/lib/python3/dist-packages/ufw/util.py", line 427, in under_ssh
    ppid = get_ppid(pid)
  File "/usr/lib/python3/dist-packages/ufw/util.py", line 419, in get_ppid
    ppid = open(name).readlines()[0].split(')')[1].split()[1]
IndexError: list index out of range

During handling of the above exception, another exception occurred:

Traceback (most recent call last):
  File "/usr/sbin/ufw", line 138, in <module>
    not ui.continue_under_ssh():
  File "/usr/lib/python3/dist-packages/ufw/frontend.py", line 901, in continue_under_ssh
    if self.backend.do_checks and ufw.util.under_ssh(): # pragma: no cover
  File "/usr/lib/python3/dist-packages/ufw/util.py", line 457, in under_ssh
    return under_ssh(ppid)
  File "/usr/lib/python3/dist-packages/ufw/util.py", line 457, in under_ssh
    return under_ssh(ppid)
  File "/usr/lib/python3/dist-packages/ufw/util.py", line 457, in under_ssh
    return under_ssh(ppid)
  [Previous line repeated 1 more time]
  File "/usr/lib/python3/dist-packages/ufw/util.py", line 434, in under_ssh
    raise ValueError(err_msg)
ValueError: Couldn't find parent pid for '373'
```

firewalldをインストールする方向で試してみる
'https://code.launchpad.net/ubuntu/+source/firewalld'

```
$ git clone https://git.launchpad.net/ubuntu/+source/firewalld
Cloning into 'firewallld'...
Username for 'https://git.launchpad.net':
```

一旦中断。

別の方法を模索する。
'https://computingforgeeks.com/install-and-use-firewalld-on-ubuntu/'
ここを参考に

```
$ sudo apt update
$ sudo apt install firewalld
$ sudo systemctl enable firewalld
$ sudo systemctl start firewalld
```
パッケージ管理ソフトのaptをアップデートして、firewalldインストールして、起動時にfirewalldが起動するようにして、startで今firewalldを起動する。

```
$ systemctl status firewalld.service
● firewalld.service - firewalld - dynamic firewall daemon
     Loaded: loaded (/lib/systemd/system/firewalld.service; enabled; vendor preset: enabled)
     Active: active (running) since Thu 2023-08-17 14:38:20 JST; 5min ago
       Docs: man:firewalld(1)
   Main PID: 1484 (firewalld)
      Tasks: 2 (limit: 9371)
     Memory: 24.1M
     CGroup: /system.slice/firewalld.service
             └─1484 /usr/bin/python3 /usr/sbin/firewalld --nofork --nopid

Aug 17 14:38:20 DESKTOP-F5G6OIO systemd[1]: Starting firewalld - dynamic firewall daemon...
Aug 17 14:38:20 DESKTOP-F5G6OIO systemd[1]: Started firewalld - dynamic firewall daemon.
Aug 17 14:38:20 DESKTOP-F5G6OIO firewalld[1484]: ERROR: 'python-nftables' failed: internal:0:0-0: Error: Could not proc>


                                                 JSON blob:
                                                 {"nftables": [{"metainfo": {"json_schema_version": 1}}, {"add": {"chai>
Aug 17 14:38:20 DESKTOP-F5G6OIO firewalld[1484]: ERROR: COMMAND_FAILED: 'python-nftables' failed: internal:0:0-0: Error>


                                                 JSON blob:
                                                 {"nftables": [{"metainfo": {"json_schema_version": 1
```

firewalldがactiveになっていた。
ただ、ufwにしても、firewalldにしても、pythonが原因で何かしらのエラーが出ている。

```
$ sudo firewall-cmd --state
failed
```

これは長い闘いになりそうだ。

```
$ systemctl status ufw
● ufw.service - Uncomplicated firewall
     Loaded: loaded (/lib/systemd/system/ufw.service; enabled; vendor preset: enabled)
     Active: active (exited) since Thu 2023-08-17 13:02:34 JST; 1h 54min ago
       Docs: man:ufw(8)
   Main PID: 97 (code=exited, status=0/SUCCESS)

Aug 17 13:02:34 DESKTOP-F5G6OIO systemd[1]: Starting Uncomplicated firewall...
Aug 17 13:02:34 DESKTOP-F5G6OIO systemd[1]: Finished Uncomplicated firewall.
```

あれ？　エラーが発生していない。

```
$ sudo ufw status
Status: inactive
```

とにかくpythonがなにかやらかしているようなので、ちょっと確認

```
$ cd /
$ ls /usr/bin
```
```
 gresource                            pygettext3.10                      xxd
 groff                                python3                            xz
 grog                                 python3.10                         xzcat
```
(前後省略)

pythonが2つある。
たぶん片方はAnaconda。もう片方は所属コミュニティの活動で子供向け科学教室の教材(pythonでシューティングゲームを作ろう)のデモプレイ時にインストールしたやつ。

```
$ ls /usr/lib
```

```
cnf-update-db      gnupg             mime                 python2.7      systemd              wsl
command-not-found  gnupg2            modprobe.d           python3        sysusers.d           x86_64-linux-gnu
compat-ld          gold-ld           modules-load.d       python3.10     tc
console-setup      groff             netplan              python3.11     terminfo
```
(前後省略)

pythonが4つとは一体。

>Traceback (most recent call last):
  File "/usr/lib/python3/dist-packages/ufw/util.py", line 427, in under_ssh
    ppid = get_ppid(pid)
  File "/usr/lib/python3/dist-packages/ufw/util.py", line 419, in get_ppid
    ppid = open(name).readlines()[0].split(')')[1].split()[1]
IndexError: list index out of range

これを見る限り、python3に問題がありそう。

> firewalld[1484]: ERROR: 'python-nftables' failed: internal:0:0-0: Error: Could

こっちのエラー文

'https://qiita.com/bashaway/items/e405d59d92670fbc5341'

> CentOS8ではfirewalldが動作していて、nftablesが裏で動作しているので、nftablesとしてのデーモンは休んでいるみたい。

今操作しているOSはUbuntuだが、同じ仕組みだとすると、firewalldが使いたいnftablesをpythonが使用している状態ということか?

```
$ sudo nft list tables
table inet firewalld
```

あれ？　firewalldしかいない。
ということは、「firewalldが使いたいnftablesをpythonが使用している状態」ではなく、「firewalldとpython3は依存関係のファイル」ということだろうか？

いや、firewalldとufwは共存できないということなのか？

```
$ apt remove -y firewalld
```
仮想マシンからログアウトし、Anacondaとpython3.7.9をアンインストール

```
$ sudo ufw enable
[sudo] password for shira:
Traceback (most recent call last):
  File "/usr/lib/python3/dist-packages/ufw/util.py", line 427, in under_ssh
    ppid = get_ppid(pid)
  File "/usr/lib/python3/dist-packages/ufw/util.py", line 419, in get_ppid
    ppid = open(name).readlines()[0].split(')')[1].split()[1]
IndexError: list index out of range

During handling of the above exception, another exception occurred:

Traceback (most recent call last):
  File "/usr/sbin/ufw", line 138, in <module>
    not ui.continue_under_ssh():
  File "/usr/lib/python3/dist-packages/ufw/frontend.py", line 901, in continue_under_ssh
    if self.backend.do_checks and ufw.util.under_ssh(): # pragma: no cover
  File "/usr/lib/python3/dist-packages/ufw/util.py", line 457, in under_ssh
    return under_ssh(ppid)
  File "/usr/lib/python3/dist-packages/ufw/util.py", line 457, in under_ssh
    return under_ssh(ppid)
  File "/usr/lib/python3/dist-packages/ufw/util.py", line 457, in under_ssh
    return under_ssh(ppid)
  [Previous line repeated 1 more time]
  File "/usr/lib/python3/dist-packages/ufw/util.py", line 434, in under_ssh
    raise ValueError(err_msg)
ValueError: Couldn't find parent pid for '383'
```

```
$ sudo apt install firewalld
$ sudo systemctl start firewalld
$ sudo firewall-cmd --state
failed
$ systemctl status firewalld.service
● firewalld.service - firewalld - dynamic firewall daemon
     Loaded: loaded (/lib/systemd/system/firewalld.service; enabled; vendor preset: enabled)
     Active: active (running) since Thu 2023-08-17 16:17:16 JST; 4min 8s ago
       Docs: man:firewalld(1)
   Main PID: 589 (firewalld)
      Tasks: 2 (limit: 9371)
     Memory: 28.4M
     CGroup: /system.slice/firewalld.service
             └─589 /usr/bin/python3 /usr/sbin/firewalld --nofork --nopid

Aug 17 16:17:16 DESKTOP-F5G6OIO systemd[1]: Starting firewalld - dynamic firewall daemon...
Aug 17 16:17:16 DESKTOP-F5G6OIO systemd[1]: Started firewalld - dynamic firewall daemon.
Aug 17 16:17:16 DESKTOP-F5G6OIO firewalld[589]: ERROR: 'python-nftables' failed: internal:0:0-0: Error: Could not proce>


                                                JSON blob:
                                                {"nftables": [{"metainfo": {"json_schema_version": 1}}, {"add": {"chain>
Aug 17 16:17:16 DESKTOP-F5G6OIO firewalld[589]: ERROR: COMMAND_FAILED: 'python-nftables' failed: internal:0:0-0: Error:>


                                                JSON blob:
                                                {"nftables": [{"metainfo": {"json_schema_version": 1}}, {"add": {"chain>
lines 1-22/22 (END)
```

エラーの内容は変化なし。
関係はなさそうなので、さっきアンインストールしたAnacondaを復元。

エラーメッセージに書かれているファイルを見てみる。
```
$ ls /usr/lib/python3/dist-packages/ufw
__init__.py  __pycache__  applications.py  backend.py  backend_iptables.py  common.py  frontend.py  parser.py  util.py
```

色々探し回った挙句、ipv6を無効にすると解決する可能性があるとの記述を発見。
'https://stackoverflow.com/questions/70622426/centos-8-firewalld-error-command-failed-python-nftables-failed'

また、nftablesをiptablesにするという手段についても書いてあった。

'https://www.server-memo.net/centos-settings/centos7/disable-ipv6.html'
ipv6を無効にするとSELinuxに影響が出ると書いてあるページを発見。

SELinuxの無効化が要件に入っているので、それを先にやってしまおう。

'https://access.redhat.com/documentation/ja-jp/red_hat_enterprise_linux/8/html/using_selinux/enabling_and_disabling_selinux-disabling_selinux_changing-selinux-states-and-modes'

```
$ cat /etc/selinux/config
cat: /etc/selinux/config: No such file or directory
$ cd /
$ ls /etc/selinux
semanage.conf
$ cat /etc/selinux/semanage.conf
# Authors: Jason Tang <jtang@tresys.com>
#
# Copyright (C) 2004-2005 Tresys Technology, LLC
#
#  This library is free software; you can redistribute it and/or
#  modify it under the terms of the GNU Lesser General Public
#  License as published by the Free Software Foundation; either
#  version 2.1 of the License, or (at your option) any later version.
#
#  This library is distributed in the hope that it will be useful,
#  but WITHOUT ANY WARRANTY; without even the implied warranty of
#  MERCHANTABILITY or FITNESS FOR A PARTICULAR PURPOSE.  See the GNU
#  Lesser General Public License for more details.
#
#  You should have received a copy of the GNU Lesser General Public
#  License along with this library; if not, write to the Free Software
#  Foundation, Inc., 51 Franklin St, Fifth Floor, Boston, MA  02110-1301  USA
#
# Specify how libsemanage will interact with a SELinux policy manager.
# The four options are:
#
#  "source"     - libsemanage manipulates a source SELinux policy
#  "direct"     - libsemanage will write directly to a module store.
#  /foo/bar     - Write by way of a policy management server, whose
#                 named socket is at /foo/bar.  The path must begin
#                 with a '/'.
#  foo.com:4242 - Establish a TCP connection to a remote policy
#                 management server at foo.com.  If there is a colon
#                 then the remainder is interpreted as a port number;
#                 otherwise default to port 4242.
module-store = direct

# When generating the final linked and expanded policy, by default
# semanage will set the policy version to POLICYDB_VERSION_MAX, as
# given in <sepol/policydb.h>.  Change this setting if a different
# version is necessary.
#policy-version = 19

# expand-check check neverallow rules when executing all semanage commands.
# Large penalty in time if you turn this on.
expand-check=0

# By default, semanage will generate policies for the SELinux target.
# To build policies for Xen, uncomment the following line.
#target-platform = xen
```

よくわからない。英語をそのまま追ってもよくわからない。翻訳にかけてもよくわからない。
'https://qiita.com/hanaita0102/items/5d3675e4dc1530b255ba'

```
$ getenforce
Command 'getenforce' not found, but can be installed with:
sudo apt install selinux-utils
```
まさか、SELinux自体が存在しない！？

'https://tex2e.github.io/blog/selinux/ubuntu-install-selinux'
'https://wiki.ubuntu.com/SELinux?_ga=2.16369908.316112255.1692094768-2137818511.1692094768
これらによると、そもそも存在していない可能性が高い。
2つ目のリンク先、最終更新が2012とか書いてある。古すぎる。

```
$ sudo systemctl stop apparmor
$ systemctl status apparmor.service
○ apparmor.service - Load AppArmor profiles
     Loaded: loaded (/lib/systemd/system/apparmor.service; enabled; vendor preset: enabled)
     Active: inactive (dead)
  Condition: start condition failed at Thu 2023-08-17 22:35:30 JST; 38min ago
             └─ ConditionSecurity=apparmor was not met
       Docs: man:apparmor(7)
             https://gitlab.com/apparmor/apparmor/wikis/home/

Aug 17 22:35:30 DESKTOP-F5G6OIO systemd[1]: Condition check resulted in Load AppArmor profiles being skipped.
```
SElinuxの代わりだというapparmorを止めることに成功した。

'https://www.server-memo.net/centos-settings/centos7/disable-ipv6.html'
ネットワークの状態を確認してみる。
```
$ man ip
IP(8)                                                                     Linux                                                                     IP(8)

NAME
       ip - show / manipulate routing, network devices, interfaces and tunnels

SYNOPSIS
       ip [ OPTIONS ] OBJECT { COMMAND | help }

       ip [ -force ] -batch filename

       OBJECT := { link | address | addrlabel | route | rule | neigh | ntable | tunnel | tuntap | maddress | mroute | mrule | monitor | xfrm | netns |
               l2tp | tcp_metrics | token | macsec | vrf | mptcp | ioam }

       OPTIONS := { -V[ersion] | -h[uman-readable] | -s[tatistics] | -d[etails] | -r[esolve] | -iec | -f[amily] { inet | inet6 | link } | -4 | -6 | -B |
               -0 | -l[oops] { maximum-addr-flush-attempts } | -o[neline] | -rc[vbuf] [size] | -t[imestamp] | -ts[hort] | -n[etns] name | -N[umeric] |
               -a[ll] | -c[olor] | -br[ief] | -j[son] | -p[retty] }

OPTIONS
       -V, -Version
              Print the version of the ip utility and exit.

       -h, -human, -human-readable
              output statistics with human readable values followed by suffix.

       -b, -batch <FILENAME>
              Read commands from provided file or standard input and invoke them.  First failure will cause termination of ip.

       -force Don't terminate ip on errors in batch mode.  If there were any errors during execution of the commands, the application return code will be
              non zero.

       -s, -stats, -statistics
              Output more information. If the option appears twice or more, the amount of information increases.  As a rule, the information is statis‐
              tics or some time values.

       -d, -details
              Output more detailed information.

       -l, -loops <COUNT>
              Specify maximum number of loops the 'ip address flush' logic will attempt before giving up. The default is 10.  Zero (0) means loop until
```

```
$ ip a
1: lo: <LOOPBACK,UP,LOWER_UP> mtu 65536 qdisc noqueue state UNKNOWN group default qlen 1000
    link/loopback 00:00:00:00:00:00 brd 00:00:00:00:00:00
    inet 127.0.0.1/8 scope host lo
       valid_lft forever preferred_lft forever
    inet6 ::1/128 scope host
       valid_lft forever preferred_lft forever
2: eth0: <BROADCAST,MULTICAST,UP,LOWER_UP> mtu 1500 qdisc mq state UP group default qlen 1000
    link/ether 00:15:5d:4b:2a:c4 brd ff:ff:ff:ff:ff:ff
    inet 192.168.88.8/20 brd 192.168.95.255 scope global eth0
       valid_lft forever preferred_lft forever
    inet6 fe80::215:5dff:fe4b:2ac4/64 scope link
       valid_lft forever preferred_lft forever
```
inet6がいた。

inet6とかnftablesを触る前に、もう一度ufwを動かせないか足搔いてみようと思う。

google chromeで"ufw list index out of range"と検索したらこんなサイトがヒットした。
'https://superuser.com/questions/1775776/enabling-ufw-failed-with-ubuntu-from-wsl2'

全く同じ状態になっている人を発見。
WSLのバグかぁ、どうしようもないではないか！
一応、解決方法が書いてあったので、試してみる。

まず、使用できるバージョンを確認。

```
$ sudo apt update;apt policy ufw
```
```
ufw:
  Installed: 0.36.1-4build1
  Candidate: 0.36.1-4ubuntu0.1
```
> Update: It's fixed in version 0.36.2. However, 0.36.2 may not be available for your Ubuntu version yet. 

version 0.36.2でこのバグが修正されたらしいが、version 0.36.2、Candidateされてない。

```
$ cd /usr/lib/python3/dist-packages/ufw
$ sudo vim util.py
```

419行目のこれを

```
ppid = open(name).readlines()[0].split(')')[1].split()[1]
```
```
ppid = open(name).readlines()[0].split(')',1)[1].split()[1]
```
これに変更して

```
$ cd /
$ sudo ufw enable
Traceback (most recent call last):
  File "/usr/lib/python3/dist-packages/ufw/util.py", line 427, in under_ssh
    ppid = get_ppid(pid)
  File "/usr/lib/python3/dist-packages/ufw/util.py", line 421, in get_ppid
    return int(ppid)
ValueError: invalid literal for int() with base 10: 'S'

During handling of the above exception, another exception occurred:

Traceback (most recent call last):
  File "/usr/sbin/ufw", line 138, in <module>
    not ui.continue_under_ssh():
  File "/usr/lib/python3/dist-packages/ufw/frontend.py", line 901, in continue_under_ssh
    if self.backend.do_checks and ufw.util.under_ssh(): # pragma: no cover
  File "/usr/lib/python3/dist-packages/ufw/util.py", line 457, in under_ssh
    return under_ssh(ppid)
  File "/usr/lib/python3/dist-packages/ufw/util.py", line 457, in under_ssh
    return under_ssh(ppid)
  File "/usr/lib/python3/dist-packages/ufw/util.py", line 457, in under_ssh
    return under_ssh(ppid)
  [Previous line repeated 1 more time]
  File "/usr/lib/python3/dist-packages/ufw/util.py", line 434, in under_ssh
    raise ValueError(err_msg)
ValueError: Couldn't find parent pid for '413'
```

よく見返したら、"r"が抜けてた。

```
$ cd /usr/lib/python3/dist-packages/ufw
$ sudo vim util.py
```
```
    ppid = open(name).readlines()[0].rsplit(')',1)[1].split()[1]
```
```
$ sudo ufw enable
Firewall is active and enabled on system startup
```

やっとFirewallが有効になった。

今日はここまで。